Start to run Python Script
Traceback (most recent call last):
  File "/home/ubuntu/muse-job-api/muse-job-api.py", line 44, in <module>
    s3_client.upload_file(filename, bucketname, foldername+filename)
  File "/home/ubuntu/.local/share/virtualenvs/muse-job-api-KkNLlmec/lib/python3.10/site-packages/boto3/s3/inject.py", line 143, in upload_file
    return transfer.upload_file(
  File "/home/ubuntu/.local/share/virtualenvs/muse-job-api-KkNLlmec/lib/python3.10/site-packages/boto3/s3/transfer.py", line 292, in upload_file
    future.result()
  File "/home/ubuntu/.local/share/virtualenvs/muse-job-api-KkNLlmec/lib/python3.10/site-packages/s3transfer/futures.py", line 103, in result
    return self._coordinator.result()
  File "/home/ubuntu/.local/share/virtualenvs/muse-job-api-KkNLlmec/lib/python3.10/site-packages/s3transfer/futures.py", line 266, in result
    raise self._exception
  File "/home/ubuntu/.local/share/virtualenvs/muse-job-api-KkNLlmec/lib/python3.10/site-packages/s3transfer/tasks.py", line 269, in _main
    self._submit(transfer_future=transfer_future, **kwargs)
  File "/home/ubuntu/.local/share/virtualenvs/muse-job-api-KkNLlmec/lib/python3.10/site-packages/s3transfer/upload.py", line 585, in _submit
    upload_input_manager.provide_transfer_size(transfer_future)
  File "/home/ubuntu/.local/share/virtualenvs/muse-job-api-KkNLlmec/lib/python3.10/site-packages/s3transfer/upload.py", line 244, in provide_transfer_size
    self._osutil.get_file_size(transfer_future.meta.call_args.fileobj)
  File "/home/ubuntu/.local/share/virtualenvs/muse-job-api-KkNLlmec/lib/python3.10/site-packages/s3transfer/utils.py", line 247, in get_file_size
    return os.path.getsize(filename)
  File "/usr/lib/python3.10/genericpath.py", line 50, in getsize
    return os.stat(filename).st_size
FileNotFoundError: [Errno 2] No such file or directory: 'page50_sample_job_descriptions_test.csv'
PYTHON RUNNING FAILED
[ERROR:] RETURN CODE:  1
[ERROR:] REFER TO THE LOG FOR THE REASON FOR THE FAILURE.
